2023-10-20 11:29:44 INFO open for scan: /home/powerop/work/dense/EmoTx/EmoTx-CVPR2023/wandb/offline-run-20231020_073553-3g27sobw/run-3g27sobw.wandb
2023-10-20 11:29:48 ERROR Retry attempt failed:
Traceback (most recent call last):
  File "/home/powerop/.local/lib/python3.6/site-packages/urllib3/connectionpool.py", line 696, in urlopen
    self._prepare_proxy(conn)
  File "/home/powerop/.local/lib/python3.6/site-packages/urllib3/connectionpool.py", line 964, in _prepare_proxy
    conn.connect()
  File "/home/powerop/.local/lib/python3.6/site-packages/urllib3/connection.py", line 365, in connect
    self._tunnel()
  File "/opt/app/conda/lib/python3.6/http/client.py", line 919, in _tunnel
    message.strip()))
OSError: Tunnel connection failed: 502 Bad Gateway

During handling of the above exception, another exception occurred:

Traceback (most recent call last):
  File "/home/powerop/.local/lib/python3.6/site-packages/requests/adapters.py", line 450, in send
    timeout=timeout
  File "/home/powerop/.local/lib/python3.6/site-packages/urllib3/connectionpool.py", line 756, in urlopen
    method, url, error=e, _pool=self, _stacktrace=sys.exc_info()[2]
  File "/home/powerop/.local/lib/python3.6/site-packages/urllib3/util/retry.py", line 573, in increment
    raise MaxRetryError(_pool, url, error or ResponseError(cause))
urllib3.exceptions.MaxRetryError: HTTPSConnectionPool(host='api.wandb.ai', port=443): Max retries exceeded with url: /graphql (Caused by ProxyError('Cannot connect to proxy.', OSError('Tunnel connection failed: 502 Bad Gateway',)))

During handling of the above exception, another exception occurred:

Traceback (most recent call last):
  File "/home/powerop/.local/lib/python3.6/site-packages/wandb/sdk/lib/retry.py", line 108, in __call__
    result = self._call_fn(*args, **kwargs)
  File "/home/powerop/.local/lib/python3.6/site-packages/wandb/sdk/internal/internal_api.py", line 158, in execute
    return self.client.execute(*args, **kwargs)
  File "/home/powerop/.local/lib/python3.6/site-packages/wandb/vendor/gql-0.2.0/wandb_gql/client.py", line 52, in execute
    result = self._get_result(document, *args, **kwargs)
  File "/home/powerop/.local/lib/python3.6/site-packages/wandb/vendor/gql-0.2.0/wandb_gql/client.py", line 60, in _get_result
    return self.transport.execute(document, *args, **kwargs)
  File "/home/powerop/.local/lib/python3.6/site-packages/wandb/vendor/gql-0.2.0/wandb_gql/transport/requests.py", line 38, in execute
    request = requests.post(self.url, **post_args)
  File "/home/powerop/.local/lib/python3.6/site-packages/requests/api.py", line 117, in post
    return request('post', url, data=data, json=json, **kwargs)
  File "/home/powerop/.local/lib/python3.6/site-packages/requests/api.py", line 61, in request
    return session.request(method=method, url=url, **kwargs)
  File "/home/powerop/.local/lib/python3.6/site-packages/requests/sessions.py", line 529, in request
    resp = self.send(prep, **send_kwargs)
  File "/home/powerop/.local/lib/python3.6/site-packages/requests/sessions.py", line 645, in send
    r = adapter.send(request, **kwargs)
  File "/home/powerop/.local/lib/python3.6/site-packages/requests/adapters.py", line 513, in send
    raise ProxyError(e, request=request)
requests.exceptions.ProxyError: HTTPSConnectionPool(host='api.wandb.ai', port=443): Max retries exceeded with url: /graphql (Caused by ProxyError('Cannot connect to proxy.', OSError('Tunnel connection failed: 502 Bad Gateway',)))
2023-10-20 11:30:44 INFO open for scan: /home/powerop/work/dense/EmoTx/EmoTx-CVPR2023/wandb/offline-run-20231020_073553-3g27sobw/run-3g27sobw.wandb
2023-10-20 11:30:47 ERROR Retry attempt failed:
Traceback (most recent call last):
  File "/home/powerop/.local/lib/python3.6/site-packages/urllib3/connectionpool.py", line 696, in urlopen
    self._prepare_proxy(conn)
  File "/home/powerop/.local/lib/python3.6/site-packages/urllib3/connectionpool.py", line 964, in _prepare_proxy
    conn.connect()
  File "/home/powerop/.local/lib/python3.6/site-packages/urllib3/connection.py", line 365, in connect
    self._tunnel()
  File "/opt/app/conda/lib/python3.6/http/client.py", line 919, in _tunnel
    message.strip()))
OSError: Tunnel connection failed: 502 Bad Gateway

During handling of the above exception, another exception occurred:

Traceback (most recent call last):
  File "/home/powerop/.local/lib/python3.6/site-packages/requests/adapters.py", line 450, in send
    timeout=timeout
  File "/home/powerop/.local/lib/python3.6/site-packages/urllib3/connectionpool.py", line 756, in urlopen
    method, url, error=e, _pool=self, _stacktrace=sys.exc_info()[2]
  File "/home/powerop/.local/lib/python3.6/site-packages/urllib3/util/retry.py", line 573, in increment
    raise MaxRetryError(_pool, url, error or ResponseError(cause))
urllib3.exceptions.MaxRetryError: HTTPSConnectionPool(host='api.wandb.ai', port=443): Max retries exceeded with url: /graphql (Caused by ProxyError('Cannot connect to proxy.', OSError('Tunnel connection failed: 502 Bad Gateway',)))

During handling of the above exception, another exception occurred:

Traceback (most recent call last):
  File "/home/powerop/.local/lib/python3.6/site-packages/wandb/sdk/lib/retry.py", line 108, in __call__
    result = self._call_fn(*args, **kwargs)
  File "/home/powerop/.local/lib/python3.6/site-packages/wandb/sdk/internal/internal_api.py", line 158, in execute
    return self.client.execute(*args, **kwargs)
  File "/home/powerop/.local/lib/python3.6/site-packages/wandb/vendor/gql-0.2.0/wandb_gql/client.py", line 52, in execute
    result = self._get_result(document, *args, **kwargs)
  File "/home/powerop/.local/lib/python3.6/site-packages/wandb/vendor/gql-0.2.0/wandb_gql/client.py", line 60, in _get_result
    return self.transport.execute(document, *args, **kwargs)
  File "/home/powerop/.local/lib/python3.6/site-packages/wandb/vendor/gql-0.2.0/wandb_gql/transport/requests.py", line 38, in execute
    request = requests.post(self.url, **post_args)
  File "/home/powerop/.local/lib/python3.6/site-packages/requests/api.py", line 117, in post
    return request('post', url, data=data, json=json, **kwargs)
  File "/home/powerop/.local/lib/python3.6/site-packages/requests/api.py", line 61, in request
    return session.request(method=method, url=url, **kwargs)
  File "/home/powerop/.local/lib/python3.6/site-packages/requests/sessions.py", line 529, in request
    resp = self.send(prep, **send_kwargs)
  File "/home/powerop/.local/lib/python3.6/site-packages/requests/sessions.py", line 645, in send
    r = adapter.send(request, **kwargs)
  File "/home/powerop/.local/lib/python3.6/site-packages/requests/adapters.py", line 513, in send
    raise ProxyError(e, request=request)
requests.exceptions.ProxyError: HTTPSConnectionPool(host='api.wandb.ai', port=443): Max retries exceeded with url: /graphql (Caused by ProxyError('Cannot connect to proxy.', OSError('Tunnel connection failed: 502 Bad Gateway',)))
