2023-10-20 07:05:55,788 INFO    MainThread:367148 [wandb_setup.py:_flush():76] Configure stats pid to 367148
2023-10-20 07:05:55,788 INFO    MainThread:367148 [wandb_setup.py:_flush():76] Loading settings from /home/powerop/.config/wandb/settings
2023-10-20 07:05:55,788 INFO    MainThread:367148 [wandb_setup.py:_flush():76] Loading settings from /home/powerop/work/dense/EmoTx/EmoTx-CVPR2023/plot_generators/wandb/settings
2023-10-20 07:05:55,788 INFO    MainThread:367148 [wandb_setup.py:_flush():76] Loading settings from environment variables: {}
2023-10-20 07:05:55,788 INFO    MainThread:367148 [wandb_setup.py:_flush():76] Inferring run settings from compute environment: {'program': '<python with no main file>'}
2023-10-20 07:05:55,788 INFO    MainThread:367148 [wandb_init.py:_log_setup():461] Logging user logs to /home/powerop/work/dense/EmoTx/EmoTx-CVPR2023/plot_generators/wandb/run-20231020_070555-19qe7scc/logs/debug.log
2023-10-20 07:05:55,788 INFO    MainThread:367148 [wandb_init.py:_log_setup():462] Logging internal logs to /home/powerop/work/dense/EmoTx/EmoTx-CVPR2023/plot_generators/wandb/run-20231020_070555-19qe7scc/logs/debug-internal.log
2023-10-20 07:05:55,789 INFO    MainThread:367148 [wandb_init.py:_jupyter_setup():411] configuring jupyter hooks <wandb.sdk.wandb_init._WandbInit object at 0x7faeb17f8208>
2023-10-20 07:05:55,790 INFO    MainThread:367148 [wandb_init.py:init():495] calling init triggers
2023-10-20 07:05:55,790 INFO    MainThread:367148 [wandb_init.py:init():499] wandb.init called with sweep_config: {}
config: {'learning_rate': 0.02, 'architecture': 'CNN', 'dataset': 'CIFAR-100', 'epochs': 10}
2023-10-20 07:05:55,790 INFO    MainThread:367148 [wandb_init.py:init():548] starting backend
2023-10-20 07:05:55,790 INFO    MainThread:367148 [backend.py:_multiprocessing_setup():99] multiprocessing start_methods=fork,spawn,forkserver, using: spawn
2023-10-20 07:05:55,835 INFO    MainThread:367148 [backend.py:ensure_launched():217] starting backend process...
2023-10-20 07:05:55,871 INFO    MainThread:367148 [backend.py:ensure_launched():222] started backend process with pid: 368896
2023-10-20 07:05:55,872 INFO    MainThread:367148 [wandb_init.py:init():558] backend started and connected
2023-10-20 07:05:55,894 INFO    MainThread:367148 [wandb_run.py:_label_probe_notebook():1084] probe notebook
2023-10-20 07:05:55,895 INFO    MainThread:367148 [wandb_run.py:_label_probe_notebook():1094] Unable to probe notebook: 'NoneType' object has no attribute 'get'
2023-10-20 07:05:55,895 INFO    MainThread:367148 [wandb_init.py:init():634] updated telemetry
2023-10-20 07:05:56,072 INFO    MainThread:367148 [wandb_init.py:init():666] communicating run to backend with 30 second timeout
2023-10-20 07:06:24,796 ERROR   Thread-5  :367148 [retry.py:__call__():132] Retry attempt failed:
Traceback (most recent call last):
  File "/home/powerop/.local/lib/python3.6/site-packages/urllib3/connection.py", line 169, in _new_conn
    (self._dns_host, self.port), self.timeout, **extra_kw
  File "/home/powerop/.local/lib/python3.6/site-packages/urllib3/util/connection.py", line 96, in create_connection
    raise err
  File "/home/powerop/.local/lib/python3.6/site-packages/urllib3/util/connection.py", line 86, in create_connection
    sock.connect(sa)
socket.timeout: timed out

During handling of the above exception, another exception occurred:

Traceback (most recent call last):
  File "/home/powerop/.local/lib/python3.6/site-packages/urllib3/connectionpool.py", line 706, in urlopen
    chunked=chunked,
  File "/home/powerop/.local/lib/python3.6/site-packages/urllib3/connectionpool.py", line 382, in _make_request
    self._validate_conn(conn)
  File "/home/powerop/.local/lib/python3.6/site-packages/urllib3/connectionpool.py", line 1010, in _validate_conn
    conn.connect()
  File "/home/powerop/.local/lib/python3.6/site-packages/urllib3/connection.py", line 352, in connect
    conn = self._new_conn()
  File "/home/powerop/.local/lib/python3.6/site-packages/urllib3/connection.py", line 176, in _new_conn
    % (self.host, self.timeout),
urllib3.exceptions.ConnectTimeoutError: (<urllib3.connection.HTTPSConnection object at 0x7fb096415208>, 'Connection to api.wandb.ai timed out. (connect timeout=10)')

During handling of the above exception, another exception occurred:

Traceback (most recent call last):
  File "/home/powerop/.local/lib/python3.6/site-packages/requests/adapters.py", line 450, in send
    timeout=timeout
  File "/home/powerop/.local/lib/python3.6/site-packages/urllib3/connectionpool.py", line 756, in urlopen
    method, url, error=e, _pool=self, _stacktrace=sys.exc_info()[2]
  File "/home/powerop/.local/lib/python3.6/site-packages/urllib3/util/retry.py", line 573, in increment
    raise MaxRetryError(_pool, url, error or ResponseError(cause))
urllib3.exceptions.MaxRetryError: HTTPSConnectionPool(host='api.wandb.ai', port=443): Max retries exceeded with url: /graphql (Caused by ConnectTimeoutError(<urllib3.connection.HTTPSConnection object at 0x7fb096415208>, 'Connection to api.wandb.ai timed out. (connect timeout=10)'))

During handling of the above exception, another exception occurred:

Traceback (most recent call last):
  File "/home/powerop/.local/lib/python3.6/site-packages/wandb/sdk/lib/retry.py", line 108, in __call__
    result = self._call_fn(*args, **kwargs)
  File "/home/powerop/.local/lib/python3.6/site-packages/wandb/sdk/internal/internal_api.py", line 158, in execute
    return self.client.execute(*args, **kwargs)
  File "/home/powerop/.local/lib/python3.6/site-packages/wandb/vendor/gql-0.2.0/wandb_gql/client.py", line 52, in execute
    result = self._get_result(document, *args, **kwargs)
  File "/home/powerop/.local/lib/python3.6/site-packages/wandb/vendor/gql-0.2.0/wandb_gql/client.py", line 60, in _get_result
    return self.transport.execute(document, *args, **kwargs)
  File "/home/powerop/.local/lib/python3.6/site-packages/wandb/vendor/gql-0.2.0/wandb_gql/transport/requests.py", line 38, in execute
    request = requests.post(self.url, **post_args)
  File "/home/powerop/.local/lib/python3.6/site-packages/requests/api.py", line 117, in post
    return request('post', url, data=data, json=json, **kwargs)
  File "/home/powerop/.local/lib/python3.6/site-packages/requests/api.py", line 61, in request
    return session.request(method=method, url=url, **kwargs)
  File "/home/powerop/.local/lib/python3.6/site-packages/requests/sessions.py", line 529, in request
    resp = self.send(prep, **send_kwargs)
  File "/home/powerop/.local/lib/python3.6/site-packages/requests/sessions.py", line 645, in send
    r = adapter.send(request, **kwargs)
  File "/home/powerop/.local/lib/python3.6/site-packages/requests/adapters.py", line 507, in send
    raise ConnectTimeout(e, request=request)
requests.exceptions.ConnectTimeout: HTTPSConnectionPool(host='api.wandb.ai', port=443): Max retries exceeded with url: /graphql (Caused by ConnectTimeoutError(<urllib3.connection.HTTPSConnection object at 0x7fb096415208>, 'Connection to api.wandb.ai timed out. (connect timeout=10)'))
2023-10-20 07:06:26,073 INFO    MainThread:367148 [interface_shared.py:_communicate_run():326] couldn't get run from backend
2023-10-20 07:06:26,074 ERROR   MainThread:367148 [wandb_init.py:init():674] backend process timed out
2023-10-20 07:06:26,074 ERROR   MainThread:367148 [wandb_init.py:init():685] encountered error: Error communicating with wandb process
try: wandb.init(settings=wandb.Settings(start_method='fork'))
or:  wandb.init(settings=wandb.Settings(start_method='thread'))
For more info see: https://docs.wandb.ai/library/init#init-start-error
2023-10-20 07:18:57,317 WARNING MainThread:367148 [wandb_init.py:init():1064] interrupted
Traceback (most recent call last):
  File "/home/powerop/.local/lib/python3.6/site-packages/wandb/sdk/wandb_init.py", line 1043, in init
    run = wi.init()
  File "/home/powerop/.local/lib/python3.6/site-packages/wandb/sdk/wandb_init.py", line 689, in init
    backend.cleanup()
  File "/home/powerop/.local/lib/python3.6/site-packages/wandb/sdk/backend/backend.py", line 248, in cleanup
    self.wandb_process.join()
  File "/opt/app/conda/lib/python3.6/multiprocessing/process.py", line 124, in join
    res = self._popen.wait(timeout)
  File "/opt/app/conda/lib/python3.6/multiprocessing/popen_fork.py", line 50, in wait
    return self.poll(os.WNOHANG if timeout == 0.0 else 0)
  File "/opt/app/conda/lib/python3.6/multiprocessing/popen_fork.py", line 28, in poll
    pid, sts = os.waitpid(self.pid, flag)
KeyboardInterrupt
